2024-11-15 21:49:30,216 - satellite_A - ERROR - Exception on /send [POST]
Traceback (most recent call last):
  File "/Users/aryansingh/Desktop/packet-routing/satellite_network/.venv/lib/python3.12/site-packages/flask/app.py", line 1511, in wsgi_app
    response = self.full_dispatch_request()
               ^^^^^^^^^^^^^^^^^^^^^^^^^^^^
  File "/Users/aryansingh/Desktop/packet-routing/satellite_network/.venv/lib/python3.12/site-packages/flask/app.py", line 919, in full_dispatch_request
    rv = self.handle_user_exception(e)
         ^^^^^^^^^^^^^^^^^^^^^^^^^^^^^
  File "/Users/aryansingh/Desktop/packet-routing/satellite_network/.venv/lib/python3.12/site-packages/flask/app.py", line 917, in full_dispatch_request
    rv = self.dispatch_request()
         ^^^^^^^^^^^^^^^^^^^^^^^
  File "/Users/aryansingh/Desktop/packet-routing/satellite_network/.venv/lib/python3.12/site-packages/flask/app.py", line 902, in dispatch_request
    return self.ensure_sync(self.view_functions[rule.endpoint])(**view_args)  # type: ignore[no-any-return]
           ^^^^^^^^^^^^^^^^^^^^^^^^^^^^^^^^^^^^^^^^^^^^^^^^^^^^^^^^^^^^^^^^^
  File "/Users/aryansingh/Desktop/packet-routing/satellite_network/middleware/validators.py", line 24, in decorated_function
    return f(*args, **kwargs)
           ^^^^^^^^^^^^^^^^^^
  File "/Users/aryansingh/Desktop/packet-routing/satellite_network/routes/message_routes.py", line 19, in send_message
    return controller.handle_send(request.get_json())
           ^^^^^^^^^^^^^^^^^^^^^^^^^^^^^^^^^^^^^^^^^^
  File "/Users/aryansingh/Desktop/packet-routing/satellite_network/controllers/message_controller.py", line 53, in handle_send
    self.satellite.network_map[next_hop]}/send',
    ~~~~~~~~~~~~~~~~~~~~~~~~~~^^^^^^^^^^
TypeError: unhashable type: 'list'
